Workbook
Name 攻击: _xlfn.LAMBDA(_xlpm.X,_xlpm.Y,_xlpm.X*第一套计算!$J$2/第一套计算!$E$5)
Name 破防: _xlfn.LAMBDA(_xlpm.X,_xlpm.Y,(第一套计算!$G$2/(第一套计算!$E$6-_xlpm.X+第一套计算!$G$2))/(第一套计算!$G$2/(第一套计算!$E$6+第一套计算!$G$2))-1)
Name 防御: _xlfn.LAMBDA(_xlpm.X,_xlpm.Y,1-(第一套计算!$G$16/(第一套计算!$B$27+_xlpm.X+第一套计算!$G$16))/(第一套计算!$G$16/(第一套计算!$B$27+第一套计算!$G$16)))

Sheet 4.1.1抗拆内功计算器
B1: 4.1.1进攻团抗拆内功计算器（攻防一体） 【只有标蓝区域可填写】【计算器目的是算内功词条提升】 | P1: 抗拆总分 | R1: 评价 | AA1: 空拆总分 | AC1: 评价
M2: 第一套评分 | P2: =E16+E28 -> 3445 | R2: =VLOOKUP(P2,$AC$38:$AD$44,2,TRUE) -> 盼之吧没开玩笑 | T2: 祝福 【偷拆不会被逮捕】 | X2: 第一套评分 | AA2: =E16 -> 3445 | AC2: =VLOOKUP(AA2,$AC$47:$AD$53,2,TRUE) -> 盼之吧没开玩笑 | AE2: 祝福 【偷拆不会被逮捕】
B3: 表格作者：满天丶星河 公式参考：折字 表格优化：休寒 | M3: 第二套评分 | P3: =J16+J28 -> 5070.2727 | R3: =VLOOKUP(P3,$AC$38:$AD$44,2,TRUE) -> 盼之吧没开玩笑 | T3: 祝福 【抗拆不会乱循环】 | X3: 第二套评分 | AA3: =J16 -> 5070.2727 | AC3: =VLOOKUP(AA3,$AC$47:$AD$53,2,TRUE) -> 饮水机管理员 | AE3: 祝福 【抗拆不会乱循环】
B5: 第一套（标蓝区域填内功词条） | G5: 第二套（默认试用基准内功） | L5: 职业 必填 | M5: 职业 | P5: 职业 必填 | Q5: 输出属性满数值 | T5: 坦度属性满数值 | W5: 更新记录/数值说明
B6: 攻击类型 | C6: 数值 | D6: 收益 | E6: 总评分 | G6: 词条类型 | H6: 数值 | I6: 收益 | J6: 评分 | K6: 差值对比 | M6: 狂澜
B7: 攻击 | D7: =C7/$R$7*$S$7 -> 0 | E7: =IF(M12="一线牵",#REF!*10000,D7*10000) -> 0 | G7: 攻击 | I7: =H7/$R$7*$S$7 -> 0 | J7: =IF(M12="一线牵",#REF!*10000,I7*10000) -> 0 | K7: =IF(D7<>0,(J7-E7)/E7,1) -> 1 | M7: 基础配置 | Q7: 攻击 | R7: 33 | S7: =1.65% -> 0.0165 | T7: 根骨 | U7: =$R$8 -> 10 | V7: =U7*74/U15*V15 -> 0.0094086781
B8: 力量/气海 | D8: =C8/$R$8*$S$8 -> 0 | E8: =IF(M12="一线牵",#REF!*10000,D8*10000) -> 0 | G8: 力量/气海 | I8: =H8/$R$8*$S$8 -> 0 | J8: =IF(M12="一线牵",#REF!*10000,I8*10000) -> 0 | K8: =IF(D8<>0,(J8-E8)/E8,1) -> 1 | M8: 金周天 | N8: 3金 | O8: 3木不影响词条计算，故不参与配置。火周天稀释内功及词条，不要纠结火周天多了会减分的问题。火、木周天实战不好量化收益，也不适合参与评分计算 | Q8: 力量/气海 | R8: 10 | S8: =(R8*2.5)/R7*S7+R8/R10*S10 -> 0.016136364 | T8: 耐力 | U8: =$R$8 -> 10 | V8: =U8*2.75/U10*V10 -> 0.010833333 | W8: 1力量＝2.5攻击+1破防
B9: 最大+最小攻 | D9: =C9/$R$9*$S$9 -> 0 | E9: =IF(M12="一线牵",#REF!*10000,D9*10000) -> 0 | G9: 最大+最小攻 | H9: =31*6 -> 186 | I9: =H9/$R$9*$S$9 -> 0.0465 | J9: =IF(M12="一线牵",#REF!*10000,I9*10000) -> 465 | K9: =IF(D9<>0,(J9-E9)/E9,1) -> 1 | M9: 火周天 | N9: 3火 | Q9: 最大/小攻 | R9: 36 | S9: =R9/2/R7*S7 -> 0.009 | T9: 内/外功防御 | U9: =$R$9 -> 36 | V9: =U9/2/U10*V10 -> 0.0070909091 | W9: 1身法＝6会心+2会抗
B10: 破防 | D10: =C10/$R$10*$S$10 -> 0 | E10: =IF(M12="一线牵",#REF!*10000,D10*10000) -> 0 | G10: 破防 | H10: =28*6 -> 168 | I10: =H10/$R$10*$S$10 -> 0.061090909 | J10: =IF(M12="一线牵",#REF!*10000,I10*10000) -> 610.90909 | K10: =IF(D10<>0,(J10-E10)/E10,1) -> 1 | M10: 承影追击 | N10: 0.09 | Q10: 破防 | R10: 33 | S10: =1.2% -> 0.012 | T10: 防御 | U10: =$R$10 -> 33 | V10: =1.3% -> 0.013 | W10: 1根骨=1攻击+74气血
B11: 流派克制% | D11: =C11/$R$11*$S$11 -> 0 | E11: =IF(M12="一线牵",#REF!*10000,D11*10000) -> 0 | G11: 流派克制% | I11: =H11/$R$11*$S$11 -> 0 | J11: =IF(M12="一线牵",#REF!*10000,I11*10000) -> 0 | K11: =IF(D11<>0,(J11-E11)/E11,1) -> 1 | M11: 承影共鸣 | N11: 0.018 | Q11: 流派克制% | R11: 0.012 | S11: =1.1% -> 0.011 | T11: 流派抵御% | U11: =$R$11 -> 0.012 | V11: =U11/1.07 -> 0.011214953 | W11: 1耐力=1攻击+2.75防御
B12: 会心 | D12: =C12/$R$12*$S$12 -> 0 | E12: =IF(M12="一线牵",#REF!*10000,D12*10000) -> 0 | G12: 会心 | H12: =57*6 -> 342 | I12: =H12/$R$12*$S$12 -> 0.046636364 | J12: =IF(M12="一线牵",#REF!*10000,I12*10000) -> 466.36364 | K12: =IF(D12<>0,(J12-E12)/E12,1) -> 1 | M12: 绝技 | N12: 0.12 | Q12: 会心 | R12: 66 | S12: =0.9% -> 0.009 | T12: 抗会心 | U12: =$R$12 -> 66 | V12: =1.2% -> 0.012
B13: 身法 | D13: =C13/$R$13*$S$13 -> 0 | E13: =IF(M12="一线牵",#REF!*10000,D13*10000) -> 0 | G13: 身法 | I13: =H13/$R$13*$S$13 -> 0 | J13: =IF(M12="一线牵",#REF!*10000,I13*10000) -> 0 | K13: =IF(D13<>0,(J13-E13)/E13,1) -> 1 | M13: 内功特效 | N13: =[1]计算器!F24 -> 0.17272727 | Q13: 身法 | R13: =R8 -> 10 | S13: =R13*6/R12*S12 -> 0.0081818182 | T13: 身法 | U13: =$R$8 -> 10 | V13: =U13*2/U12*V12 -> 0.0036363636 | X13: 内功增伤计算
B14: 根骨+耐力 | D14: =C14/$R$14*$S$14 -> 0 | E14: =IF(M12="一线牵",#REF!*10000,D14*10000) -> 0 | G14: 根骨+耐力 | I14: =H14/$R$14*$S$14 -> 0 | J14: =IF(M12="一线牵",#REF!*10000,I14*10000) -> 0 | K14: =IF(D14<>0,(J14-E14)/E14,1) -> 1 | M14: 内功特效参考 | N14: =([1]计算器!F13+[1]计算器!J20+[1]计算器!J23+[1]计算器!J34)/1.1 -> 0.17272727 | Q14: 根骨/耐力 | R14: 10 | S14: =R14/R7*S7 -> 0.005 | T14: 抗内/外功会心 | U14: =$R$9*2 -> 72 | V14: =U14/2/U12*V12 -> 0.0065454545 | W14: 面板增伤 | X14: {=IFERROR(IF(VLOOKUP("承影锋烁",M20:N26,2,0)="普通",4%,6%),0)+IFERROR(IF(VLOOKUP("日月两仪",M20:N26,2,0)="普通",5.6%,8.1%),0)+IFERROR(IF(VLOOKUP("五蕴谣",M20:N26,2,0)="普通",2%,3.5%),0)+IFERROR(IF(VLOOKUP("纳百观 ",M20:N26,2,0)="普通",2%,3.5%),0)+_xlfn.IFS(N9="3火",4%,N9="2火",2.4%,N9="1火",1.2%)} -> 0.1
B15: 赛年强化 | D15: =C15/$R$15*$S$15 -> 0 | E15: =IF(M12="一线牵",#REF!*10000,D15*10000) -> 0 | G15: 赛年强化 | I15: =H15/$R$15*$S$15 -> 0 | J15: =IF(M12="一线牵",#REF!*10000,I15*10000) -> 0 | K15: =IF(D15<>0,(J15-E15)/E15,1) -> 1 | Q15: 赛年强化 | R15: 0.017 | S15: 0.0147 | T15: 气血 | U15: 991 | V15: =1.4%*0.9 -> 0.0126 | W15: 入战增伤
B16: 输出总收益 | D16: =SUM(D7:D15) -> 0 | E16: =D16*10000+O30 -> 3445 | G16: 输出总收益 | I16: =SUM(I7:I15) -> 0.15422727 | J16: =I16*10000+T30 -> 5070.2727 | K16: =IF(D16<>0,(J16-E16)/E16,1) -> 1 | R16: 均值收益 | S16: =SUM(S7:S15)/COUNT(S7:S15) -> 0.011279798 | U16: 均值收益 | V16: =SUM(V7:V14)/COUNT(V7:V14) -> 0.0092162115 | W16: 总增伤
B18: 坦度词条（标蓝区域填内功词条） | G18: 坦度词条 | M18: 第一套内功 | O18: 分数 | R18: 第二套内功 | T18: 分数
B19: 根骨 | D19: =C19/$U$7*$V$7 -> 0 | E19: =D19*10000 -> 0 | G19: 根骨 | I19: =H19/$U$7*$V$7 -> 0 | J19: =I19*10000 -> 0 | K19: =IF(D19<>0,(J19-E19)/E19,1) -> 1 | M19: 稀有内功 | N19: 是否灵韵 | O19: 分数 | P19: 灵韵分数 | R19: 稀有内功 | S19: 是否灵韵 | T19: 分数 | U19: 灵韵分数
B20: 耐力 | D20: =C20/$U$8*$V$8 -> 0 | E20: =D20*10000 -> 0 | G20: 耐力 | I20: =H20/$U$8*$V$8 -> 0 | J20: =I20*10000 -> 0 | K20: =IF(D20<>0,(J20-E20)/E20,1) -> 1 | M20: 灼星贯日 | N20: 普通 | O20: =ROUND(_xlfn.XLOOKUP(M20,[1]计算器!$I$20:$I$38,[1]计算器!$K$20:$K$38,0)*10000,0) -> 745 | P20: =IF(N20="灵韵",ROUND(_xlfn.XLOOKUP(M20,[1]计算器!$I$20:$I$38,[1]计算器!$L$20:$L$38,0)*10000,0),0) -> 0 | R20: 灼星贯日 | S20: 普通 | T20: =ROUND(_xlfn.XLOOKUP(R20,[1]计算器!$I$20:$I$38,[1]计算器!$K$20:$K$38,0)*10000,0) -> 745 | U20: =IF(S20="灵韵",ROUND(_xlfn.XLOOKUP(R20,[1]计算器!$I$20:$I$38,[1]计算器!$L$20:$L$38,0)*10000,0),0) -> 0
B21: 内+外功防御 | D21: =C21/$U$9*$V$9 -> 0 | E21: =D21*10000 -> 0 | G21: 内+外功防御 | I21: =H21/$U$9*$V$9 -> 0 | J21: =I21*10000 -> 0 | K21: =IF(D21<>0,(J21-E21)/E21,1) -> 1 | M21: 承影锋烁 | N21: 普通 | O21: =ROUND(_xlfn.XLOOKUP(M21,[1]计算器!$I$20:$I$38,[1]计算器!$K$20:$K$38,0)*10000,0) -> 662 | P21: =IF(N21="灵韵",ROUND(_xlfn.XLOOKUP(M21,[1]计算器!$I$20:$I$38,[1]计算器!$L$20:$L$38,0)*10000,0),0) -> 0 | R21: 承影锋烁 | S21: 普通 | T21: =ROUND(_xlfn.XLOOKUP(R21,[1]计算器!$I$20:$I$38,[1]计算器!$K$20:$K$38,0)*10000,0) -> 662 | U21: =IF(S21="灵韵",ROUND(_xlfn.XLOOKUP(R21,[1]计算器!$I$20:$I$38,[1]计算器!$L$20:$L$38,0)*10000,0),0) -> 0
B22: 防御 | D22: =C22/$U$10*$V$10 -> 0 | E22: =D22*10000 -> 0 | G22: 防御 | I22: =H22/$U$10*$V$10 -> 0 | J22: =I22*10000 -> 0 | K22: =IF(D22<>0,(J22-E22)/E22,1) -> 1 | M22: 绝电惊沙 | N22: 普通 | O22: =ROUND(_xlfn.XLOOKUP(M22,[1]计算器!$I$20:$I$38,[1]计算器!$K$20:$K$38,0)*10000,0) -> 580 | P22: =IF(N22="灵韵",ROUND(_xlfn.XLOOKUP(M22,[1]计算器!$I$20:$I$38,[1]计算器!$L$20:$L$38,0)*10000,0),0) -> 0 | R22: 绝电惊沙 | S22: 普通 | T22: =ROUND(_xlfn.XLOOKUP(R22,[1]计算器!$I$20:$I$38,[1]计算器!$K$20:$K$38,0)*10000,0) -> 580 | U22: =IF(S22="灵韵",ROUND(_xlfn.XLOOKUP(R22,[1]计算器!$I$20:$I$38,[1]计算器!$L$20:$L$38,0)*10000,0),0) -> 0 | Y22: 基础伤害 | Z22: a | AA22: 5.5%a
B23: 流派抵御% | D23: =C23/$U$11*$V$11 -> 0 | E23: =D23*10000 -> 0 | G23: 流派抵御% | I23: =H23/$U$11*$V$11 -> 0 | J23: =I23*10000 -> 0 | K23: =IF(D23<>0,(J23-E23)/E23,1) -> 1 | M23: 普通内功 | N23: 是否灵韵 | R23: 普通内功 | S23: 是否灵韵 | Y23: 局内平均减伤 | Z23: 0.5
B24: 抗会心 | D24: =C24/$U$12*$V$12 -> 0 | E24: =D24*10000 -> 0 | G24: 抗会心 | I24: =H24/$U$12*$V$12 -> 0 | J24: =I24*10000 -> 0 | K24: =IF(D26<>0,(J26-E26)/E26,1) -> 1 | M24: 众妙 | N24: 普通 | O24: =ROUND(_xlfn.XLOOKUP(M24,[1]计算器!$I$20:$I$38,[1]计算器!$K$20:$K$38,0)*10000,0) -> 550 | P24: =IF(N24="灵韵",ROUND(_xlfn.XLOOKUP(M24,[1]计算器!$I$20:$I$38,[1]计算器!$L$20:$L$38,0)*10000,0),0) -> 0 | R24: 众妙 | S24: 普通 | T24: =ROUND(_xlfn.XLOOKUP(R24,[1]计算器!$I$20:$I$38,[1]计算器!$K$20:$K$38,0)*10000,0) -> 550 | U24: =IF(S24="灵韵",ROUND(_xlfn.XLOOKUP(R24,[1]计算器!$I$20:$I$38,[1]计算器!$L$20:$L$38,0)*10000,0),0) -> 0 | Y24: 局内士气 | Z24: 40%增伤
B25: 身法 | D25: =C25/$U$13*$V$13 -> 0 | E25: =D25*10000 -> 0 | G25: 身法 | I25: =H25/$U$13*$V$13 -> 0 | J25: =I25*10000 -> 0 | K25: =IF(D25<>0,(J25-E25)/E25,1) -> 1 | M25: 锻寒芒 | N25: 普通 | O25: =ROUND(_xlfn.XLOOKUP(M25,[1]计算器!$I$20:$I$38,[1]计算器!$K$20:$K$38,0)*10000,0) -> 469 | P25: =IF(N25="灵韵",ROUND(_xlfn.XLOOKUP(M25,[1]计算器!$I$20:$I$38,[1]计算器!$L$20:$L$38,0)*10000,0),0) -> 0 | R25: 锻寒芒 | S25: 普通 | T25: =ROUND(_xlfn.XLOOKUP(R25,[1]计算器!$I$20:$I$38,[1]计算器!$K$20:$K$38,0)*10000,0) -> 469 | U25: =IF(S25="灵韵",ROUND(_xlfn.XLOOKUP(R25,[1]计算器!$I$20:$I$38,[1]计算器!$L$20:$L$38,0)*10000,0),0) -> 0 | Y25: 局内实际伤害 | Z25: 0.7a | AA25: 5.5%a
B26: 抗内/外功会心 | D26: =C26/$U$14*$V$14 -> 0 | E26: =D26*10000 -> 0 | G26: 抗内+外功会心 | I26: =H26/$U$14*$V$14 -> 0 | J26: =I26*10000 -> 0 | K26: =IF(D28<>0,(J28-E28)/E28,1) -> 1 | M26: 五蕴谣 | N26: 普通 | O26: =ROUND(_xlfn.XLOOKUP(M26,[1]计算器!$I$20:$I$38,[1]计算器!$K$20:$K$38,0)*10000,0) -> 439 | P26: =IF(N26="灵韵",ROUND(_xlfn.XLOOKUP(M26,[1]计算器!$I$20:$I$38,[1]计算器!$L$20:$L$38,0)*10000,0),0) -> 0 | R26: 楚狂歌 | S26: 普通 | T26: =ROUND(_xlfn.XLOOKUP(R26,[1]计算器!$I$20:$I$38,[1]计算器!$K$20:$K$38,0)*10000,0) -> 522 | U26: =IF(S26="灵韵",ROUND(_xlfn.XLOOKUP(R26,[1]计算器!$I$20:$I$38,[1]计算器!$L$20:$L$38,0)*10000,0),0) -> 0 | AA26: =5.5%/0.7 -> 0.078571429
B27: 气血 | D27: =IF(C27>12505,(C27-12504)/$U$15*$V$15,0) -> 0 | E27: =D27*10000 -> 0 | G27: 气血 | I27: =IF(H27>12505,(H27-12504)/$U$15*$V$15,0) -> 0 | J27: =I27*10000 -> 0 | K27: =IF(D28<>0,(J28-E28)/E28,1) -> 1 | O27: =ROUND(_xlfn.XLOOKUP(M27,[1]计算器!$I$20:$I$38,[1]计算器!$K$20:$K$38,0)*10000,0) -> 0 | P27: =IF(N27="灵韵",ROUND(_xlfn.XLOOKUP(M27,[1]计算器!$I$20:$I$38,[1]计算器!$L$20:$L$38,0)*10000,0),0) -> 0 | T27: =ROUND(_xlfn.XLOOKUP(R27,[1]计算器!$I$20:$I$38,[1]计算器!$K$20:$K$38,0)*10000,0) -> 0 | U27: =IF(S27="灵韵",ROUND(_xlfn.XLOOKUP(R27,[1]计算器!$I$20:$I$38,[1]计算器!$L$20:$L$38,0)*10000,0),0) -> 0 | AA27: =5.5*1.5 -> 8.25
B28: 坦度总收益(已折算输出） | D28: =SUM(D19:D27)/([1]计算器!$L$64/[1]计算器!$M$64) -> 0 | E28: =D28*10000 -> 0 | G28: 坦度总收益(已折算输出） | I28: =SUM(I19:I27)/([1]计算器!$L$64/[1]计算器!$M$64) -> 0 | J28: =I28*10000 -> 0 | O28: =ROUND(_xlfn.XLOOKUP(M28,[1]计算器!$I$20:$I$38,[1]计算器!$K$20:$K$38,0)*10000,0) -> 0 | P28: =IF(N28="灵韵",ROUND(_xlfn.XLOOKUP(M28,[1]计算器!$I$20:$I$38,[1]计算器!$L$20:$L$38,0)*10000,0),0) -> 0 | T28: =ROUND(_xlfn.XLOOKUP(R28,[1]计算器!$I$20:$I$38,[1]计算器!$K$20:$K$38,0)*10000,0) -> 0 | U28: =IF(S28="灵韵",ROUND(_xlfn.XLOOKUP(R28,[1]计算器!$I$20:$I$38,[1]计算器!$L$20:$L$38,0)*10000,0),0) -> 0
B29: 1力量＝2.5攻击+1破防 | M29: 计数 | N29: =COUNTIF(N20:N26,"灵韵") -> 0 | O29: =SUM(O20:O28) -> 3445 | P29: =SUM(P20:P28) -> 0 | R29: 计数 | S29: =COUNTIF(S20:S26,"灵韵") -> 0 | T29: =SUM(T20:T28) -> 3528 | U29: =SUM(U20:U28) -> 0
B30: 1身法＝6会心+2会抗 | M30: 总分 | O30: =SUM(O29:P29) -> 3445 | R30: 总分 | T30: =SUM(T29:U29) -> 3528
B31: 1根骨＝1攻击+74气血
B32: 1耐力＝1攻击+2.75防御
B33: 联赛内禁疗严重，即便有奶也有防暴毙收益
B34: 气血按理论的0.9倍坦度计算
B35: 气血内功基础12504，额外气血才算收益，计算过程已自动减去基础血量
B36: 额外攻击%，血河特6%，神相特5%，碎梦特2%
L37: 词条数量 | M37: 坦度1.5%=输出1%收益折算 | Q37: 100分＝1%输出收益 | AB37: 抗拆
L38: 无内功 | M38: 0 | P38: 不如试用内功的东西，疑似伪人 | U38: 多数账号约3.5-4.5词条之间 均5词条以上便算大号 均6词条以上凤毛麟角 | AB38: 试用 | AC38: 0 | AD38: 盼之吧没开玩笑
L39: =AB39 -> 3.2词条 | M39: =6100 -> 6100 | P39: 均3输出+1.5坦度词条，可担饮水机大任 | AB39: 3.2词条 | AC39: =M39 -> 6100 | AD39: 饮水机管理员
L40: =AB40 -> 3.5词条 | M40: =M39+$S$16*6*10000*0.3 -> 6303.0364 | P40: 均3输出+2坦度词条，塔已有取死之道 | AB40: 3.5词条 | AC40: =M40 -> 6303.0364 | AD40: 合格塔兵
L41: =AB41 -> 4.5词条 | M41: =M40+$S$16*6*10000*1 -> 6979.8242 | P41: 均4输出+1.5坦度词条，拆之巅、傲世间 | AB41: 4.5词条 | AC41: =M41 -> 6979.8242 | AD41: 拆之巅、傲世间
L42: =AB42 -> 5.5词条 | M42: =M41+$S$16*6*10000*1 -> 7656.6121 | P42: 均4.5输出+1.5坦度词条，手握日月拆星辰 | AB42: 5.5词条 | AC42: =M42 -> 7656.6121 | AD42: 手握日月拆星辰
...

Sheet 4.1.1.3抗拆内功计算器
A1: 4.1.1版本进攻团内功计算器（仅做参考）
A2: 表格作者：满天丶星河 公式套用：折字为安 表格优化：休寒 | AG2: 第1套内功 | AJ2: 第2套内功
B3: 4.1.1版本词条满数值收益概念一览 | K3: 职业选择 | P3: 战斗时长 | R3: 120 | U3: 抗拆内功评分区间表述一览 | AH3: 增伤 | AI3: 占比 | AK3: 增伤 | AL3: 占比 | AO3: 职业 | AP3: 攻击系数 | AQ3: 破防系数 | AR3: 会心系数
B4: 攻击 | C4: 33 | D4: {=IFERROR(_xlfn.IFS(K4=AO9,攻击(C4,0)*1.05*(1+AP9/第一套计算!J2),K4=AO11,攻击(C4,0)*1.05*(1+AP11/第一套计算!J2),K4=AO12,攻击(C4,0)*1.05*(1+AP12/第一套计算!J2)),攻击(C4,0)*1.05)} -> 0.015603824 | E4: 攻击 均值收益 | F4: 根骨 | G4: =$C$5 -> 10 | H4: =G4*74/G12*H12 -> 0.0092070636 | I4: 防守 均值收益 | K4: 潮光 | P4: 士气 | R4: 7 | U4: 0 | V4: 抗拆 | W4: 0 | X4: 空拆 | Y4: 不如试用，疑似伪人 | AB4: 试用金火内功 抗拆7k4分 空拆6k9分 | AD4: 试用 | AF4: 灼星贯日 | AG4: =ROUND(360+J26*2000,0) -> 678 | AI4: =AI22 -> 0.036 | AJ4: =ROUND(360+J39*2000,0) -> 708 | AL4: =AL22 -> 0.036 | AO4: 龙吟 | AQ4: 0.05 | BC4: =U4 -> 0 | BD4: 盼之吧没开玩笑 | BG4: =W11 -> 0 | BH4: 盼之吧没开玩笑
B5: 力量/气海 | C5: 10 | D5: =(C5*2.5)/C4*D4+C5/C7*D7 -> 0.01560887 | F5: 耐力 | G5: =$C$5 -> 10 | H5: =G5*2.75/G7*H7 -> 0.010416667 | P5: 标红为更高、标绿为更低 | U5: 7400 | V5: >均3.1词条 | W5: 6900 | X5: >均2.4词条 | Y5: 可担饮水机大任 | AD5: 4词条 | AF5: 承影锋烁 | AG5: =ROUND((4%/(L26-L19)+(C20+C21)*0.3)*10000,0) -> 695 | AH5: =L19 -> 0.06 | AJ5: =ROUND((4%/(L39-L32)+(C20+C21)*0.3)*10000,0) -> 760 | AK5: =L32 -> 0.04 | AO5: 狂澜 | BC5: =U5 -> 7400 | BD5: 饮水机管理员 | BG5: =W5 -> 6900 | BH5: 饮水机管理员
B6: 最大/小攻 | C6: 36 | D6: =C6/2/C4*D4 -> 0.0085111765 | F6: 内/外功防御 | G6: =$C$6 -> 36 | H6: =G6/2/G7*H7 -> 0.0068181818 | K6: 抗拆评级 | P6: 内功 | Q6: 周天 | R6: 输出词条 | S6: 坦度词条 | T6: 灵韵词条 | U6: =U5+$E$7*6*10000*0.9 -> 8045.6131 | V6: >均4词条 | W6: =W5+$E$7*6*10000*1.6 -> 8047.7567 | X6: >均4词条 | Y6: 塔已有取死之道 | AD6: 4.5词条 | AF6: 日月两仪 | AG6: =ROUND(5.6%/($L$26-L20)*10000,0) -> 477 | AH6: =L33 -> 0 | AJ6: =ROUND(5.6%/(L39-L33)*10000,0) -> 538 | AK6: =IFERROR(IF(VLOOKUP(AI6,#REF!,2,0)="普通",5.6%,8.1%),0) -> 0 | AO6: 惊鸿 | BC6: =U6 -> 8045.6131 | BD6: 合格塔兵 | BG6: =W6 -> 8047.7567 | BH6: 合格塔兵
B7: 破防 | C7: 33 | D7: {=破防(C7,0)*0.95} -> 0.012499711 | E7: =AVERAGE(D4:D12) -> 0.011955799 | F7: 防御 | G7: =$C$7 -> 33 | H7: =1.25% -> 0.0125 | I7: =AVERAGE(H4:H11) -> 0.0086117211 | K7: 第一套评分 | L7: =SUM(P7:T7) -> 9000 | N7: =VLOOKUP(L7,$BC$4:$BD$10,2,TRUE) -> 拆之巅、傲世间 | P7: =ROUND(G26,0) -> 3237 | Q7: =ROUND(SUM($D$16:$D$19),0) -> 1777 | R7: =ROUND($Q$26,0) -> 2634 | S7: =ROUND(U26,0) -> 576 | T7: =$H$26 -> 776 | U7: =U6+$E$7*6*10000*1 -> 8762.9611 | V7: >均5词条 | W7: =W6+$E$7*6*10000*1 -> 8765.1046 | X7: >均5词条 | Y7: 拆之巅、傲世间 | AD7: 5词条 | AF7: 绝电惊沙 | AG7: 550 | AJ7: 550 | AO7: 潮光 | AV7: 3火 | AW7: 2火 | AX7: 1火 | BC7: =U7 -> 8762.9611 | BD7: 拆之巅、傲世间 | BG7: =W7 -> 8765.1046 | BH7: 拆之巅、傲世间
B8: 流派克制% | C8: 0.012 | D8: =1.1% -> 0.011 | F8: 流派抵御% | G8: =$C$8 -> 0.012 | H8: =G8/1.07 -> 0.011214953 | K8: 第二套评分 | L8: =SUM(P8:T8) -> 7609 | N8: =VLOOKUP(L8,$BC$4:$BD$10,2,TRUE) -> 饮水机管理员 | P8: =ROUND(G39,0) -> 3547 | Q8: =ROUND(SUM($D$16:$D$19),0) -> 1777 | R8: =ROUND($Q$40,0) -> 1709 | S8: =ROUND(U40,0) -> 576 | T8: =$H$39 -> 0 | U8: =U7+$E$7*6*10000*0.5 -> 9121.635 | V8: >均5.5词条 | W8: =W7+$E$7*6*10000*0.5 -> 9123.7786 | X8: >均5.5词条 | Y8: 手握日月拆星辰 | AD8: 5.5词条 | AO8: 九灵 | AU8: 面板增伤 | AV8: 0.04 | AW8: 0.024 | AX8: 0.012 | BC8: =U8 -> 9121.635 | BD8: 手握日月拆星辰 | BG8: =W8 -> 9123.7786 | BH8: 手握日月拆星辰
B9: 会心 | C9: 66 | D9: {=会心(C9,0)*0.9} -> 0.012206869 | F9: 抗会心 | G9: =$C$9 -> 66 | H9: {=会抗(G9,0)} -> 0.010136358 | U9: =U8+$E$7*6*10000*0.5 -> 9480.309 | V9: >均6词条 | W9: =W8+$E$7*6*10000*0.5 -> 9482.4525 | X9: >均6词条 | Y9: 世间无我这般人 | AD9: 6词条 | AO9: 血河 | AP9: 0.06 | AU9: 入战增伤 | AV9: 0.016 | AW9: 0.008 | AX9: 0.004 | BC9: =U9 -> 9480.309 | BD9: 世间无我这般人 | BG9: =W9 -> 9482.4525 | BH9: 世间无我这般人
B10: 身法 | C10: =C5 -> 10 | D10: =C10*6/C9*D9 -> 0.011097154 | F10: 身法 | G10: =$C$5 -> 10 | H10: =G10*2/G9*H9 -> 0.0030716236 | K10: 空拆评级 | P10: 内功 | Q10: 周天 | R10: 输出词条 | S10: 坦度词条 | T10: 灵韵词条 | U10: =U9+$E$7*6*10000*0.5 -> 9838.9829 | V10: >均6.5词条 | W10: =W9+$E$7*6*10000*0.5 -> 9841.1265 | X10: >均6.5词条 | Y10: 拆道万古如长夜 | AD10: 6.5词条 | AF10: 破釜 | AG10: 510 | AJ10: 510 | AO10: 玄机 | AR10: 0.05 | AU10: 增伤数值 | AV10: =AV8+(AV9*5+AV9*2*5+AV9*3*5+AV9*4*5+AV9*5*($R$3-20))/$R$3 -> 0.11333333 | AW10: =AW8+(AW9*5+AW9*2*5+AW9*3*5+AW9*4*5+AW9*5*($R$3-20))/$R$3 -> 0.060666667 | AX10: =AX8+(AX9*5+AX9*2*5+AX9*3*5+AX9*4*5+AX9*5*($R$3-20))/$R$3 -> 0.030333333 | BC10: =U10 -> 9838.9829 | BD10: 拆道万古如长夜 | BG10: =W10 -> 9841.1265 | BH10: 拆道万古如长夜
B11: 根骨/耐力 | C11: 10 | D11: =C11/C4*D4 -> 0.0047284314 | F11: 抗内/外功会心 | G11: =$C$6*2 -> 72 | H11: =G11/2/G9*H9 -> 0.0055289224 | K11: 第一套评分 | L11: =SUM(P11:T11) -> 8424 | N11: =VLOOKUP(L11,$BG$4:$BH$10,2,TRUE) -> 合格塔兵 | P11: =ROUND(G26,0) -> 3237 | Q11: =ROUND(SUM($D$16:$D$19),0) -> 1777 | R11: =ROUND($Q$26,0) -> 2634 | S11: / | T11: =$H$26 -> 776 | U11: 试用内功：抗拆7410（约2.4攻+0.76坦度收益，均3.2收益）空拆6884（约2.4攻收益） | AF11: 击衰 | AG11: =ROUND(450*(1-J19-J21),0) -> 434 | AJ11: =ROUND(450*(1-J32-J34),0) -> 418 | AO11: 神相 | AP11: 0.05
B12: 赛年强化 | C12: 0.017 | D12: =C12/L39 -> 0.016346154 | F12: 气血 | G12: 991 | H12: =1.37%*0.9 -> 0.01233 | K12: 第二套评分 | L12: =SUM(P12:T12) -> 7033 | N12: =VLOOKUP(L12,$BG$4:$BH$10,2,TRUE) -> 饮水机管理员 | P12: =ROUND(G39,0) -> 3547 | Q12: =ROUND(SUM($D$16:$D$19),0) -> 1777 | R12: =ROUND($Q$40,0) -> 1709 | S12: / | T12: =$H$39 -> 0 | U12: 抗拆 权重 | V12: 输出 | W12: 坦度 | X12: 100分＝1%输出收益 | AF12: 贯山月 | AG12: 280 | AJ12: 280 | AO12: 碎梦 | AP12: 0.02 | AV12: 3金 | AW12: 2金 | AX12: 1金
V13: =1-W13 -> 0.65 | W13: 0.35 | AF13: 惊羽 | AG13: 470 | AJ13: 470 | AO13: 破铁 | AU13: 占比 | AV13: 0.05 | AW13: 0.028 | AX13: 0.014 | BC13: 试用内功词条
AF14: 锻寒芒 | AG14: 500 | AJ14: 500 | AO14: 御铁 | AU14: 会伤 | AV14: 0.08 | AW14: 0.048 | AX14: 0.024 | BC14: 会心 | BD14: 57
B15: 第一套周天选择 | D15: 分数 | E15: 第一套内功 | G15: 分数 | I15: 特效占比计算 | K15: 内功增伤计算 | N15: 第一套内功及词条搭配区 | AO15: 镇海 | AU15: 实际增伤 | AV15: {=AV13+会伤(AV14,0)} -> 0.078352964 | AW15: {=AW13+会伤(AW14,0)} -> 0.045011778 | AX15: {=AX13+会伤(AX14,0)} -> 0.022505889 | BC15: 破防 | BD15: 28
B16: 金周天 | C16: 3金 | D16: {=ROUND(_xlfn.IFS(C16="1金",$AX$15,C16="2金",$AW$15,C16="3金",$AV$15,C16="无",)*10000,0)} -> 784 | E16: 稀有内功选择区 | G16: 分数 | H16: 灵韵分数 | I16: 1金 | J16: =IF($C$16=I16,$AX$13,0) -> 0 | K16: 1火 | L16: =IF($C$17=K16,$AX$10,0) -> 0 | N16: 攻击词条 | O16: 数值填写 | P16: 收益 | Q16: 总评分 | R16: 防御词条 | S16: 数值填写 | T16: 收益 | U16: 总评分 | AF16: 破重云 | AG16: =ROUND(150*0.5+280*0.5+4%/(1+$R$4*5%+IF($C$55="有",$D$55,0))*10000,0) -> 492 | AI16: =J22 -> 0 | AJ16: =ROUND(150*0.5+280*0.5+4%/(1+$R$4*5%+IF($C$55="有",$D$55,0))*10000,0) -> 492 | AL16: 0.015 | AO16: 天问 | AV16: 3土 | AW16: 2土 | AX16: 1土 | AY16: 减伤取值 | BC16: 最大攻击 | BD16: 31
B17: 火周天 | C17: 3火 | D17: {=ROUND(_xlfn.IFS(C17=K16,L16/($L$26-L16),C17=K17,L17/($L$26-L17),C17=K18,L18/($L$26-L18),C17="无",)*10000,0)} -> 993 | E17: 日月两仪 | F17: 灵韵 | G17: =IFERROR(VLOOKUP(E17,$AF$4:$AJ$7,2,0),0) -> 477 | H17: =ROUND(IF(F17="普通",0,IF(E17="灼星贯日",G17*0.5,G17*0.45)),0) -> 215 | I17: 2金 | J17: =IF($C$16=I17,$AW$13,0) -> 0 | K17: 2火 | L17: =IF($C$17=K17,$AW$10,0) -> 0 | N17: 攻击 | O17: 183 | P17: =O17/$C$4*$D$4 -> 0.086530294 | Q17: =P17*10000 -> 865.30294 | R17: 根骨 | S17: 29 | T17: =S17/$G$4*$H$4 -> 0.026700484 | U17: =T17*10000 -> 267.00484 | AF17: 凌穹 | AG17: 450 | AI17: =J24 -> 0 | AJ17: 450 | AL17: 0.041 | AU17: 气血 | AV17: 0.015 | AW17: 0.03 | AX17: 0.06 | AY17: 60%血 | BC17: 内功防御 | BD17: 31
B18: 木周天 | C18: 无 | D18: {=ROUND(_xlfn.IFS(C18="1木",1/(1-7%)-1,C18="2木",1/(1-15%)*-1,C18="3木",1/(1-25%)-1,C18="无",)*10000*0.4*0.5,0)} -> 0 | E18: 承影锋烁 | F18: 灵韵 | G18: =IFERROR(VLOOKUP(E18,$AF$4:$AJ$7,2,0),0) -> 695 | H18: =ROUND(IF(F18="普通",0,IF(E18="灼星贯日",G18*0.5,G18*0.45)),0) -> 313 | I18: 3金 | J18: =IF($C$16=I18,$AV$13,0) -> 0.05 | K18: 3火 | L18: =IF($C$17=K18,$AV$10,0) -> 0.11333333 | N18: 力量/气海 | O18: 14 | P18: =O18/$C$5*$D$5 -> 0.021852417 | Q18: =P18*10000 -> 218.52417 | R18: 耐力 | S18: 10 | T18: =S18/$G$5*$H$5 -> 0.010416667 | U18: =T18*10000 -> 104.16667 | AF18: 沧浪行 | AG18: =ROUND(5.4%/(L26-L23)*10000,0) -> 431 | AH18: =L23 -> 0 | AJ18: =ROUND(5.4%/(L39-L36)*10000,0) -> 519 | AK18: =IFERROR(IF(VLOOKUP(AI18,#REF!,2,0)="普通",5.4%,7.2%),0) -> 0 | AU18: 减伤 | AV18: 0.006 | AW18: 0.012 | AX18: 0.02 | AY18: 4层减伤 | BC18: 外功防御 | BD18: 31
B19: 土周天 | C19: 无 | D19: {=ROUND(_xlfn.IFS(C19="1土",$AV$19,C19="2土",$AW$19,C19="3土",$AX$19,C19="无",)*10000/$V$13*$W$13,0)} -> 0 | E19: 绝电惊沙 | F19: 灵韵 | G19: =IFERROR(VLOOKUP(E19,$AF$4:$AJ$7,2,0),0) -> 550 | H19: =ROUND(IF(F19="普通",0,IF(E19="灼星贯日",G19*0.5,G19*0.45)),0) -> 248 | I19: 灼星贯日 | J19: =IFERROR(IF(VLOOKUP("灼星贯日",$E$17:$F$19,2,0)="普通",3.6%,3.6%*1.5),0) -> 0 | K19: 承影锋烁 | L19: =IFERROR(IF(VLOOKUP(K19,$E$17:$F$24,2,0)="普通",4%,6%),0) -> 0.06 | N19: 最大+最小攻 | O19: 213 | P19: =O19/$C$6*$D$6 -> 0.050357794 | Q19: =P19*10000 -> 503.57794 | R19: 内+外功防御 | S19: 94 | T19: =S19/$G$6*$H$6 -> 0.01780303 | U19: =T19*10000 -> 178.0303 | AF19: 裁锋 | AG19: 480 | AI19: =J23 -> 0 | AJ19: 480 | AL19: 0.027 | AU19: 坦度 | AV19: =AV17*0.9+AV18*4/(1+15%) -> 0.034369565 | AW19: =AW17*0.9+AW18*4/(1+15%) -> 0.06873913 | AX19: =AX17*0.9+AX18*4/(1+15%) -> 0.12356522 | BC19: 抗外会心 | BD19: 62
B20: 承影追击 | C20: 0.1 | E20: 普通内功选择区 | G20: / | H20: / | I20: 绝电惊沙 | J20: =IFERROR(IF(VLOOKUP("绝电惊沙",$E$17:$F$19,2,0)="普通",5.2%,7.3%),0) -> 0.073 | K20: 日月两仪 | L20: =IFERROR(IF(VLOOKUP(K20,$E$17:$F$24,2,0)="普通",5.6%,8.1%),0) -> 0.081 | N20: 破防 | O20: 56 | P20: =O20/$C$7*$D$7 -> 0.021211631 | Q20: =P20*10000 -> 212.11631 | R20: 防御 | S20: 26 | T20: =S20/$G$7*$H$7 -> 0.0098484848 | U20: =T20*10000 -> 98.484848 | BC20: 抗内会心 | BD20: 62
B21: 承影共鸣 | C21: 0.02 | E21: 众妙 | F21: 普通 | G21: =IFERROR(VLOOKUP(E21,$AF$10:$AJ$32,2,0),0) -> 505 | H21: =ROUND(IF(F21="普通",0,IF(E21=$AF$27,150/($L$26-$L$21),G21*0.3)),0) -> 0 | I21: 众妙 | J21: =IFERROR(IF(VLOOKUP("众妙",$E$21:$F$24,2,0)="普通",3.6%,3.6%*1.3),0) -> 0.036 | K21: 五蕴谣 | L21: =IFERROR(IF(VLOOKUP(K21,$E$21:$F$24,2,0)="普通",2%,3.5%),0) -> 0 | N21: 流派克制% | O21: 0.012 | P21: =O21/$C$8*$D$8 -> 0.011 | Q21: =P21*10000 -> 110 | R21: 流派抵御% | T21: =S21/$G$8*$H$8 -> 0 | U21: =T21*10000 -> 0
B22: 绝技占比 | C22: 0.1 | E22: 破釜 | F22: 普通 | G22: =IFERROR(VLOOKUP(E22,$AF$10:$AJ$32,2,0),0) -> 510 | H22: =ROUND(IF(F22="普通",0,IF(E22=$AF$27,150/($L$26-$L$21),G22*0.3)),0) -> 0 | I22: 破重云 | J22: =IFERROR(IF(VLOOKUP("破重云",$E$21:$F$24,2,0)="普通",1.5%,1.8%),0) -> 0 | K22: 纳百观 | L22: =IFERROR(IF(VLOOKUP(K22,$E$21:$F$24,2,0)="普通",2.25%,1.8%),0) -> 0 | N22: 会心 | O22: 184 | P22: =O22/$C$9*$D$9 -> 0.034031272 | Q22: =P22*10000 -> 340.31272 | R22: 抗会心 | S22: 66 | T22: =S22/$G$9*$H$9 -> 0.010136358 | U22: =T22*10000 -> 101.36358 | AF22: 众妙 | AG22: =ROUND(360+150*(1-J19-J21),0) -> 505 | AI22: =J21 -> 0.036 | AJ22: =ROUND(360+150*(1-J32-J34),0) -> 499 | AL22: 0.036
B23: 内功特效 | C23: =J26 -> 0.159 | E23: 锻寒芒 | F23: 普通 | G23: =IFERROR(VLOOKUP(E23,$AF$10:$AJ$32,2,0),0) -> 500 | H23: =ROUND(IF(F23="普通",0,IF(E23=$AF$27,150/($L$26-$L$21),G23*0.3)),0) -> 0 | I23: 裁锋 | J23: =IFERROR(IF(VLOOKUP(I23,$E$21:$F$24,2,0)="普通",2.7%,3.5%),0) -> 0 | K23: 沧浪行 | L23: =IFERROR(IF(VLOOKUP(K23,$E$21:$F$24,2,0)="普通",2.7%,3.5%),0) -> 0 | N23: 身法 | O23: 18 | P23: =O23/$C$10*$D$10 -> 0.019974877 | Q23: =P23*10000 -> 199.74877 | R23: 身法 | S23: =O23 -> 18 | T23: =S23/$G$10*$H$10 -> 0.0055289224 | U23: =T23*10000 -> 55.289224 | AF23: 斩精 | AG23: =ROUND(AG11*1.05,0) -> 456 | AJ23: =ROUND(AJ11*1.05,0) -> 439 | AX23: 1土
B24: 试用内功特效 | C24: =13.8% -> 0.138 | G24: =IFERROR(VLOOKUP(E24,$AF$10:$AJ$32,2,0),0) -> 0 | H24: =ROUND(IF(F24="普通",0,IF(E24=$AF$27,150/($L$26-$L$21),G24*0.3)),0) -> 0 | I24: 凌穹 | J24: =IFERROR(IF(VLOOKUP(I24,$E$21:$F$24,2,0)="普通",4.1%,5.2%),0) -> 0 | K24: 锻寒芒 | L24: =IFERROR(IF(VLOOKUP(K24,$E$21:$F$24,2,0)="普通",-2.5%,-3%),0) -> -0.025 | N24: 根骨+耐力 | O24: 39 | P24: =O24/$C$11*$D$11 -> 0.018440882 | Q24: =P24*10000 -> 184.40882 | R24: 抗内+外功会心 | S24: 345 | T24: =S24/$G$11*$H$11 -> 0.026492753 | U24: =T24*10000 -> 264.92753 | AF24: 楚狂歌 | AG24: 530 | AJ24: 530 | AX24: 2土
E25: 灵韵合计 | F25: =COUNTIF(F17:F24,"灵韵") -> 3 | G25: 内功总分 | H25: 灵韵总分 | I25: / | J25: / | K25: 固垒 | L25: =IFERROR(IF(VLOOKUP(K25,$E$21:$F$24,2,0)="普通",-2.5%,-3%),0) -> 0 | N25: 赛年强化 | O25: 0 | P25: =O25/$C$12*$D$12 -> 0 | Q25: =P25*10000 -> 0 | R25: 气血 | S25: 12504 | T25: =IF(S25>12505,(S25-12504)/$G$12*$H$12,0) -> 0 | U25: =T25*10000 -> 0 | AF25: 焚刃 | AG25: 100 | AJ25: 100 | AX25: 3土
G26: =SUM(G17:G24) -> 3237 | H26: =SUM(H17:H24) -> 776 | I26: 总特效 | J26: =SUM(J16:J24)/IF(SUM(J16:J24)>20%,1.1,1) -> 0.159 | K26: 总增伤 | L26: =1+SUM(L16:L25)+2.5% -> 1.2543333 | M26: 默认+3水 | N26: 攻击词条总收益 | P26: =SUM(P17:P25) -> 0.26339917 | Q26: =P26*10000 -> 2633.9917 | R26: 防御词条总收益 | T26: =SUM(T17:T25)/$V$13*$W$13 -> 0.057575915 | U26: =T26*10000 -> 575.75915 | AI26: 坦度 | AL26: 坦度
AF27: 五蕴谣 | AG27: {=ROUND(2%/(L26-L21)*10000,0)+IFERROR(_xlfn.IFS(C16="1金",D16,C17="1火",D17,C18="1木",D18,C19="1土",D19),0)} -> 159 | AH27: =L21 -> 0 | AJ27: {=ROUND(2%/(L39-L34)*10000,0)+IFERROR(_xlfn.IFS(C29="1金",D29,C30="1火",D30,C31="1木",D31,C32="1土",D32),0)} -> 192 | AK27: =IFERROR(IF(VLOOKUP(AI27,#REF!,2,0)="普通",2%,3.5%),0) -> 0
B28: 第二套周天选择 | D28: 分数 | E28: 第一套内功 | G28: 分数 | I28: 特效占比计算 | K28: 内功增伤计算 | N28: 第二套内功及词条搭配区（不建议跨周天对比） | AF28: 纳百观 | AG28: =ROUND((2.25%/(L26-L22)+AI28/$V$13*$W$13)*10000,0) -> 395 | AH28: =L22 -> 0 | AI28: 0.04 | AJ28: =ROUND((2.25%/(L39-L35)+AL28/$V$13*$W$13)*10000,0) -> 432 | AK28: =IFERROR(IF(VLOOKUP(AI28,#REF!,2,0)="普通",2.25%,3%),0) -> 0 | AL28: 0.04
B29: 金周天 | C29: 3金 | D29: {=ROUND(_xlfn.IFS(C29="1金",$AX$15,C29="2金",$AW$15,C29="3金",$AV$15,C29="无",)*10000,0)} -> 784 | E29: 稀有内功选择区 | G29: 分数 | H29: 灵韵分数 | I29: 1金 | J29: =IF($C$29="1金",1.4%,0) -> 0 | K29: 1火 | L29: =IF($C$30=K29,$AX$10,0) -> 0 | AF29: 固垒 | AG29: =ROUND((-2.5%/((L26-L25))+AI29/$V$13*$W$13)*10000,0) -> 82 | AH29: =L25 -> 0 | AI29: =6%/(1+15%) -> 0.052173913 | AJ29: =ROUND((-2.5%/(L39-L38)+AL29/$V$13*$W$13)*10000,0) -> 41 | AK29: =IFERROR(IF(VLOOKUP(AI29,#REF!,2,0)="普通",-2.5%,-3%),0) -> 0 | AL29: =6%/(1+15%) -> 0.052173913
B30: 火周天 | C30: 无 | D30: {=ROUND(_xlfn.IFS(C30=K29,L29/($L$39-L29),C30=K30,L30/($L$39-L30),C30=K31,L31/($L$39-L31),C30="无",)*10000,0)} -> 0 | E30: 灼星贯日 | F30: 普通 | G30: =IFERROR(VLOOKUP(E30,$AF$4:$AJ$7,5,0),0) -> 708 | H30: =ROUND(IF(F30="普通",0,IF(E30="灼星贯日",G30*0.5,G30*0.45)),0) -> 0 | I30: 2金 | J30: =IF($C$29="2金",2.8%,0) -> 0 | K30: 2火 | L30: =IF($C$30=K30,$AW$10,0) -> 0 | N30: 攻击词条 | O30: 数值填写 | P30: 收益 | Q30: 总评分 | R30: 防御词条 | S30: 数值填写 | T30: 收益 | U30: 总评分 | AF30: 御千障 | AG30: =ROUND((AI30/$V$13*$W$13)*10000,0) -> 242 | AI30: 0.045 | AJ30: =ROUND((AL30/$V$13*$W$13)*10000,0) -> 242 | AL30: 0.045
B31: 木周天 | C31: 无 | D31: {=ROUND(_xlfn.IFS(C31="1木",1/(1-7%)-1,C31="2木",1/(1-15%)*-1,C31="3木",1/(1-25%)-1,C31="无",)*10000*0.4*0.5,0)} -> 0 | E31: 承影锋烁 | F31: 普通 | G31: =IFERROR(VLOOKUP(E31,$AF$4:$AJ$7,5,0),0) -> 760 | H31: =ROUND(IF(F31="普通",0,IF(E31="灼星贯日",G31*0.5,G31*0.45)),0) -> 0 | I31: 3金 | J31: =IF($C$29="3金",5%,0) -> 0.05 | K31: 3火 | L31: =IF($C$30=K31,$AV$10,0) -> 0 | N31: 攻击 | P31: =O31/$C$4*$D$4 -> 0 | Q31: =P31*10000 -> 0 | R31: 根骨 | T31: =S31/$G$4*$H$4 -> 0 | U31: =T31*10000 -> 0 | AF31: 覆沙阙 | AG31: =ROUND((AI31/$V$13*$W$13)*10000,0) -> 150 | AI31: =3%/(1+8%) -> 0.027777778 | AJ31: =ROUND((AL31/$V$13*$W$13)*10000,0) -> 150 | AL31: =3%/(1+8%) -> 0.027777778
B32: 土周天 | C32: 无 | D32: {=ROUND(_xlfn.IFS(C32="1土",$AV$19,C32="2土",$AW$19,C32="3土",$AX$19,C32="无",)*10000/$V$13*$W$13,0)} -> 0 | E32: 绝电惊沙 | F32: 普通 | G32: =IFERROR(VLOOKUP(E32,$AF$4:$AJ$7,5,0),0) -> 550 | H32: =ROUND(IF(F32="普通",0,IF(E32="灼星贯日",G32*0.5,G32*0.45)),0) -> 0 | I32: 灼星贯日 | J32: =IFERROR(IF(VLOOKUP("灼星贯日",$E$30:$F$37,2,0)="普通",3.6%,3.6%*1.5),0) -> 0.036 | K32: 承影锋烁 | L32: =IFERROR(IF(VLOOKUP(K32,$E$30:$F$32,2,0)="普通",4%,6%),0) -> 0.04 | N32: 力量/气海 | P32: =O32/$C$5*$D$5 -> 0 | Q32: =P32*10000 -> 0 | R32: 耐力 | T32: =S32/$G$5*$H$5 -> 0 | U32: =T32*10000 -> 0 | AF32: 征袍 | AG32: =ROUND((AI32/$V$13*$W$13)*10000,0) -> 242 | AI32: 0.045 | AJ32: =ROUND((AL32/$V$13*$W$13)*10000,0) -> 242 | AL32: 0.045
B33: 承影追击 | C33: 0.1 | E33: 普通内功选择区 | G33: / | H33: / | I33: 绝电惊沙 | J33: =IFERROR(IF(VLOOKUP("绝电惊沙",$E$30:$F$37,2,0)="普通",5.2%,7.3%),0) -> 0.052 | K33: 日月两仪 | L33: =IFERROR(IF(VLOOKUP(K33,$E$30:$F$32,2,0)="普通",5.6%,8.1%),0) -> 0 | N33: 最大+最小攻 | O33: =31*6 -> 186 | P33: =O33/$C$6*$D$6 -> 0.043974412 | Q33: =P33*10000 -> 439.74412 | R33: 内+外功防御 | S33: =31*2*6 -> 372 | T33: =S33/$G$6*$H$6 -> 0.070454545 | U33: =T33*10000 -> 704.54545
B34: 承影共鸣 | C34: 0.02 | E34: 众妙 | F34: 普通 | G34: =IFERROR(VLOOKUP(E34,$AF$10:$AJ$32,5,0),0) -> 499 | H34: =ROUND(IF(F34="普通",0,IF(E34=$AF$27,150/($L$26-$L$21),G34*0.3)),0) -> 0 | I34: 众妙 | J34: =IFERROR(IF(VLOOKUP("众妙",$E$30:$F$37,2,0)="普通",3.6%,3.6%*1.3),0) -> 0.036 | K34: 五蕴谣 | L34: =IFERROR(IF(VLOOKUP(K34,$E$34:$F$37,2,0)="普通",2%,3.5%),0) -> 0 | N34: 破防 | O34: =28*6 -> 168 | P34: =O34/$C$7*$D$7 -> 0.063634892 | Q34: =P34*10000 -> 636.34892 | R34: 防御 | T34: =S34/$G$7*$H$7 -> 0 | U34: =T34*10000 -> 0
B35: 绝技占比 | C35: 0.1 | E35: 楚狂歌 | F35: 普通 | G35: =IFERROR(VLOOKUP(E35,$AF$10:$AJ$32,5,0),0) -> 530 | H35: =ROUND(IF(F35="普通",0,IF(E35=$AF$27,150/($L$26-$L$21),G35*0.3)),0) -> 0 | I35: 破重云 | J35: =IFERROR(IF(VLOOKUP("破重云",$E$30:$F$37,2,0)="普通",1.5%,1.8%),0) -> 0 | K35: 纳百观 | L35: =IFERROR(IF(VLOOKUP(K35,$E$34:$F$37,2,0)="普通",2.25%,1.8%),0) -> 0 | N35: 流派克制% | P35: =O35/$C$8*$D$8 -> 0 | Q35: =P35*10000 -> 0 | R35: 流派抵御% | T35: =S35/$G$8*$H$8 -> 0 | U35: =T35*10000 -> 0
B36: 内功特效 | C36: =J39 -> 0.174 | E36: 锻寒芒 | F36: 普通 | G36: =IFERROR(VLOOKUP(E36,$AF$10:$AJ$32,5,0),0) -> 500 | H36: =ROUND(IF(F36="普通",0,IF(E36=$AF$27,150/($L$26-$L$21),G36*0.3)),0) -> 0 | I36: 裁锋 | J36: =IFERROR(IF(VLOOKUP(I36,$E$30:$F$37,2,0)="普通",2.7%,3.5%),0) -> 0 | K36: 沧浪行 | L36: =IFERROR(IF(VLOOKUP(K36,$E$34:$F$37,2,0)="普通",2.7%,3.5%),0) -> 0 | N36: 会心 | O36: =57*6 -> 342 | P36: =O36/$C$9*$D$9 -> 0.063253776 | Q36: =P36*10000 -> 632.53776 | R36: 抗会心 | T36: =S36/$G$9*$H$9 -> 0 | U36: =T36*10000 -> 0
B37: 试用内功特效 | C37: 0.138 | G37: =IFERROR(VLOOKUP(E37,$AF$10:$AJ$32,5,0),0) -> 0 | H37: =ROUND(IF(F37="普通",0,IF(E37=$AF$27,150/($L$26-$L$21),G37*0.3)),0) -> 0 | I37: 凌穹 | J37: =IFERROR(IF(VLOOKUP(I37,$E$30:$F$37,2,0)="普通",4.1%,5.2%),0) -> 0 | K37: 锻寒芒 | L37: =IFERROR(IF(VLOOKUP(K37,$E$34:$F$37,2,0)="普通",-2.5%,-3%),0) -> -0.025 | N37: 身法 | P37: =O37/$C$10*$D$10 -> 0 | Q37: =P37*10000 -> 0 | R37: 身法 | S37: =O37 -> 0 | T37: =S37/$G$10*$H$10 -> 0 | U37: =T37*10000 -> 0
E38: 灵韵合计 | F38: =COUNTIF(F30:F37,"灵韵") -> 0 | G38: 内功总分 | H38: 灵韵总分 | I38: / | J38: / | K38: 固垒 | L38: =IFERROR(IF(VLOOKUP(K38,$E$34:$F$37,2,0)="普通",-2.5%,-3%),0) -> 0 | N38: 根骨+耐力 | O38: =S31+S32 -> 0 | P38: =O38/$C$11*$D$11 -> 0 | Q38: =P38*10000 -> 0 | R38: 抗内+外功会心 | S38: =62*2*6 -> 744 | T38: =S38/$G$11*$H$11 -> 0.057132198 | U38: =T38*10000 -> 571.32198
G39: =SUM(G30:G37) -> 3547 | H39: =SUM(H30:H37) -> 0 | I39: 总特效 | J39: =SUM(J29:J37)/IF(SUM(J29:J37)>20%,1.1,1) -> 0.174 | K39: 总增伤 | L39: =1+SUM(L29:L38)+2.5% -> 1.04 | M39: 默认+3水 | N39: 赛年强化 | P39: =O39/$C$12*$D$12 -> 0 | Q39: =P39*10000 -> 0 | R39: 气血 | T39: =IF(S39>12505,(S39-12504)/$G$12*$H$12,0) -> 0 | U39: =T39*10000 -> 0
N40: 攻击词条总收益 | P40: =SUM(P31:P39) -> 0.17086308 | Q40: =P40*10000 -> 1708.6308 | R40: 防御词条总收益 | T40: =SUM(T17:T25)/$V$13*$W$13 -> 0.057575915 | U40: =T40*10000 -> 575.75915
...

Sheet 更新说明
A1: 时间 | B1: 版本号 | C1: 更新说明
A2: 2026.7.6 | B2: 4.1.1.1 | C2: 4.1.1版本，制作初版拆塔内功计算器
A3: 2026.7.6 | B3: 4.1.1.2 | C3: 1.修复锻寒芒灵韵自加bug
C4: 2.修复第二套内功变动会影响基准评分的bug
C5: 3.修复坦度词条没有抗会心的bug
C6: 4.五蕴谣额外赋值240分。仅挂1金相对稳定，1火收益高但不稳定，1木收益看具体实战
A7: 2026.7.18 | B7: 4.1.1.3 | C7: 1.以171套基础重新确定收益
C8: 2.优化版面
C9: 3.加入了周天计算，其中木周天量化仅作参考
C10: 4.修复职业区分
C11: 5.修复火周天选无时乱码
C12: 6.单独计算两套内功的收益，使不同内功、周天间对比计算更符合收益（仅作参考，主要是木周天太讷了）
C13: 7.额外增加武蕴灵窍计算（仅作参考）

Sheet 第一套计算
A1: 拆塔面板 | C1: 裸面板 | D1: 哨塔属性 | I1: buff整理
A2: 最终攻击 | B2: =ROUND((C2/(1+J3)+I31+I33*2.5+I38+I39+I37)*J2,0) -> 2222 | C2: 1800 | D2: 防御 | E2: 3783 | F2: 防御系数 | G2: 1418 | I2: 百分比攻击 | J2: =1+J3+J9 -> 1.1713 | K2: 额外攻击 | L2: =SUM(L3:L10) -> 184 | M2: 破防 | O2: 会心会伤 | Q2: 内功增伤 | R2: =1+R3+R9 -> 1.097 | T2: 武蕴增伤 | U2: =1+U3 -> 1.062 | W2: 装备增伤 | Z2: 士气
A3: 最终破防 | B3: =C3+I32+I33+N9 -> 2380 | C3: 2150 | D3: 会抗 | E3: 1324 | F3: 会心系数 | G3: 568 | I3: 面板% | J3: =SUM(J4:J7) -> 0.08 | K3: 意贯天虹 | L3: 0 | M3: 百分比%（塔） | N3: =SUM(N4:N6) -> 0.074 | O3: 锻寒芒 | Q3: 面板% | R3: =SUM(R4:R8) -> 0.1 | T3: 面板% | U3: =SUM(U4:U5) -> 0.062 | W3: 面板% | X3: 0.27
A4: 最终会心 | B4: =C4+I34+I35*6+P9-P13 -> 1776 | C4: 1375 | D4: 抵御 | E4: 399 | I4: 169公孙情 | J4: 0.03 | K4: 凛夜飒雪 | L4: =0*30 -> 0 | M4: 狂澜qte | N4: 0.05 | O4: %会伤 | P4: =IFERROR(IF(VLOOKUP("锻寒芒",'4.1.1.3抗拆内功计算器'!E21:F24,2,0)="普通",6.5%,8%),0) -> 0.065 | Q4: 日月两仪 | R4: ='4.1.1.3抗拆内功计算器'!AH6 -> 0 | T4: 武蕴点 | U4: 0.027
A5: 最终会伤 | B5: =C5+P19+P4 -> 1.595 | C5: 1.42 | D5: 最终攻克 | E5: =B2+B6 -> 2601 | I5: 套装 | J5: 0.05 | K5: 花萦凌波 | L5: =N10 -> 100 | M5: 龙吟特质 | N5: =IF('4.1.1.3抗拆内功计算器'!K4="龙吟",5%,0) -> 0 | O5: %会心 | P5: =IFERROR(IF(VLOOKUP("锻寒芒",'4.1.1.3抗拆内功计算器'!E21:F24,2,0)="普通",10%,13%),0) -> 0.1 | Q5: 承影锋烁 | R5: ='4.1.1.3抗拆内功计算器'!AH5 -> 0.06 | T5: 韩飞瑛 | U5: 0.035
A6: 流派克制 | B6: =C6 -> 379 | C6: 379 | D6: 剩余防御（塔） | E6: =E2*(1-N3)-B3 -> 1123.058 | I6: 破釜 | K6: 血河特质 | L6: 40 | M6: 武蕴*拭剑逐芒 | N6: 0.024 | Q6: 五蕴谣 | R6: ='4.1.1.3抗拆内功计算器'!AH27 -> 0
A7: 内功增伤 | B7: 0.08 | C7: =8%-2.5%+1.7% -> 0.072 | D7: 剩余会心（塔） | E7: =B4-E3 -> 452 | K7: 雪绒·衔叶铃 | Q7: ='4.1.1.3抗拆内功计算器'!C17 -> 3火 | R7: {=_xlfn.IFS(Q7="3火",4%,Q7="2火",2.4%,Q7="1火",1.2%,Q7="无",0)} -> 0.04
A8: 武蕴增伤 | B8: 0.05 | C8: =$M$18+$J$17 -> 0.06 | D8: 最终会心率 | E8: =1/(1+EXP(1-E7/G3)+P5) -> 0.42981645 | K8: 鸿音buff | L8: 22 | Q8: 锻寒芒 | R8: =IFERROR(IF(VLOOKUP("锻寒芒",'4.1.1.3抗拆内功计算器'!#REF!,2,0)="普通",-2.5%,-3%),0) -> 0
A9: 装备增伤 | B9: 0.27 | C9: 0.27 | D9: 最终破防率 | E9: =G2/(E6+G2) -> 0.55803528 | I9: 入战% | J9: =SUM(J10:J15) -> 0.0913 | K9: 素问buff | L9: 22 | M9: 额外固定破防 | N9: =SUM(N10:N11) -> 110 | O9: 额外固定会心 | P9: =SUM(P10:P16) -> 157 | Q9: 入战% | R9: =SUM(R10:R14) -> -0.003
A10: 其他增伤 | B10: 0 | C10: 0 | E10: 攻击 | F10: 破防 | G10: 会心 | H10: 会伤 | I10: 169公孙情 | J10: 0.01 | M10: 花萦凌波 | N10: =ROUND(226*20/45,0) -> 100 | O10: 凛夜飒雪 | P10: =0*50 -> 0 | Q10: 沧浪行 | R10: ='4.1.1.3抗拆内功计算器'!L36 -> 0
A11: 流派克制 | B11: 0.005 | C11: 0 | D11: 数值 | E11: 33 | F11: 33 | G11: 66 | H11: 0.05 | I11: 鲸落 | J11: 0.018 | K11: 额外克制 | L11: =SUM(L12:L14) -> 27 | M11: 虞姬·美人花 | N11: =IF([2]计算器!$F$37="有",IF([2]计算器!$B$69="169项羽",14,10),0) -> 10 | O11: 清剑鸣篁·裁 | P11: 50 | Q11: 水周天 | R11: 0.025
A12: 技能增伤 | B12: 0 | C12: 0 | D12: 输出 | F12: {=破防(F11,0)} -> 0.01315759 | G12: {=会心(G11,0)} -> 0.013563188 | H12: {=会伤(H11,0)} -> 0.017720602 | I12: 云阔 | J12: 0.0333 | K12: 队友*血河 | L12: 27 | M12: 队友*龙吟 | N12: 55 | O12: 虞姬·美人花 | P12: 12 | Q12: 纳百观 | R12: =IFERROR(IF(VLOOKUP(Q12,[2]计算器!$K$43:$L$48,2,0)="普通",2.25%,2.25%*1.3),0) -> 0
D13: 会心 | I13: 清风华莚 | J13: 0.01 | M13: t职减防（塔） | N13: 30 | O13: 队友*碎梦 | P13: 47 | Q13: 沉浪 | R13: 0.012
A14: 受击方面板 | C14: 裸面板 | D14: 攻击方 | F14: 裸面板 | I14: 水月吟 | J14: 0.01 | O14: 队友*潮光 | P14: 48 | Q14: ='4.1.1.3抗拆内功计算器'!C17 -> 3火 | R14: =SUM('4.1.1.3抗拆内功计算器'!L29:L31)-R7 -> -0.04
A15: 最终气血 | B15: =C15+12504+4000+2500 -> 65004 | C15: 46000 | D15: 最终攻击 | E15: =(F15/(1+J3)+M31+M33*2.5+L2)*J2 -> 2518.8373 | F15: 1850 | G15: 防御系数 | I15: 奶妈*承影 | J15: 0.01 | O15: 苍峦惊羽 | P15: 0
A16: 最终会抗 | B16: =C16+70 -> 1150 | C16: =1030+50 -> 1080 | D16: 最终会心 | E16: =F16+M34+P9 -> 1715 | F16: 1375 | G16: 1714
A17: 会心防御 | B17: 0 | C17: 0 | D17: 最终会心伤害 | E17: =F17+P19 -> 1.53 | F17: =142% -> 1.42 | G17: 会心系数 | I17: 血河 | J17: 0.06
A18: 防御 | B18: =C18+100 -> 3550 | C18: 3450 | D18: 最终破防 | E18: =F18+M32+M33+N9-N12 -> 2448 | F18: 2180 | G18: 686 | I18: 碎梦 | J18: 0.02
A19: 流派抵御 | B19: =C19 -> 469 | C19: =229+240 -> 469 | D19: 最终流派克制 | E19: =F19+L11 -> 496 | F19: =C19 -> 469 | I19: 神相 | J19: 0.05 | O19: 额外会伤 | P19: =SUM(P20:P23) -> 0.11
A20: 内功减伤 | B20: 0 | D20: 最终内功加伤 | E20: =F20+R9 -> 0.077 | F20: 0.08 | O20: ='4.1.1.3抗拆内功计算器'!C16 -> 3金 | P20: 0.08
A21: 武蕴减伤 | B21: 0 | D21: 最终武蕴加伤 | E21: =F21 -> 0.062 | F21: 0.062 | O21: 心眼 | P21: 0.03
A22: 装备减伤 | B22: 0 | D22: 最终装备加伤 | E22: =F22 -> 0.27 | F22: 0.27
A23: 其他减伤 | B23: 0 | D23: 其他加伤 | E23: =F23 -> 0
A24: %流派抵御 | B24: 0 | D24: %流派克制 | E24: =F24+M36 -> 0.066 | F24: 0
A25: 技能减免 | B25: 0 | D25: 技能增强 | E25: =F25 -> 0 | N25: 会心增伤 | O25: （1-会心率+会心率*会伤）/（1-会心率+会心率*会伤）-1
D26: %攻击 | E26: =F26 -> 0.08 | F26: 0.08 | H26: 数值 | I26: 坦度
A27: 剩余防御人 | B27: =B18-E18 -> 1102 | D27: 最终破防率 | E27: =G16/(B27+G16) -> 0.60866477 | G27: 防御 | H27: 33 | I27: {=防御(H27,0)} -> 0.011583012
A28: 剩余会心人 | B28: =E16-B16 -> 565 | D28: 最终会心率 | E28: =1/(1+EXP(1-B28/G18))+P5 -> 0.55601776 | G28: 会抗 | H28: 66 | I28: {=会抗(H28,0)} -> 0.010136358 | N28: 破防公式 | O28: 系数/（剩余防御+系数） | R28: 原会心率 | S28: =1/(1+EXP(1-$B$28/$G$18)) -> 0.45601776
G29: 气血 | H29: 991 | I29: =H29/B15*0.9 -> 0.013720694 | N29: 会心公式 | O29: 1/（1+exp（1-剩余会心/系数） | R29: 新会心率 | S29: =1/(1+EXP(1-($B$28-H28)/$G$18)) -> 0.4322702
A30: 内功词条 | G30: 拆塔词条 | H30: 预设21 | I30: 数值 | K30: 防守词条 | L30: 预设24 | M30: 数值 | R30: 原会心增伤 | S30: =1-$S$28+$S$28*$E$17 -> 1.2416894
A31: 攻击 | B31: 26 | C31: 28 | D31: 31 | E31: 33 | G31: 攻击 | H31: 3 | I31: =H31*$D$31 -> 93 | K31: 攻击 | L31: 6 | M31: =L31*$D$31 -> 186 | R31: 新会心增伤 | S31: =1-$S$29+$S$29*$E$17 -> 1.2291032
A32: 破防 | B32: =$B$31 -> 26 | C32: =$C$31 -> 28 | D32: =$D$31 -> 31 | E32: =$E$31 -> 33 | G32: 破防 | H32: 3 | I32: =H32*$D$32 -> 93 | K32: 破防 | L32: 6 | M32: =L32*$D$32 -> 186 | S32: =1-(S31/S30) -> 0.010136358
A33: 力量 | B33: 7 | C33: 8 | D33: 9 | E33: 10 | G33: 力量 | H33: 3 | I33: =H33*$D$33 -> 27 | K33: 力量 | L33: 3 | M33: =L33*$D$33 -> 27
A34: 会心 | B34: 52 | C34: 57 | D34: 61 | E34: 66 | G34: 会心 | H34: 3 | I34: =H34*$D$34 -> 183 | K34: 会心 | L34: 3 | M34: =L34*$D$34 -> 183
A35: 身法 | B35: =$B$33 -> 7 | C35: =$C$33 -> 8 | D35: =$D$33 -> 9 | E35: =$E$33 -> 10 | G35: 身法 | H35: 2 | I35: =H35*$D$35 -> 18 | K35: 身法 | M35: =L35*$D$35 -> 0 | R35: =(1-1/(1+EXP(1-(E7+G11)/G3))+1/(1+EXP(1-(E7+G11)/G3))*B5)/(1-1/(1+EXP(1-E7/G3))+1/(1+EXP(1-E7/G3))*B5)-1 -> 0.013563188
A36: 流派克制 | B36: 0.009 | C36: 0.01 | D36: 0.011 | E36: 0.012 | G36: 流派克制 | H36: 3 | I36: =H36*$D$36 -> 0.033 | K36: 流派克制 | L36: 6 | M36: =L36*$D$36 -> 0.066 | R36: (1-1/(1+EXP(1-(E7+G11)/G3))+1/(1+EXP(1-(E7+G11)/G3))*B5)/(1-1/(1+EXP(1-E7/G3))+1/(1+EXP(1-E7/G3))*B5)-1
A37: 大小攻 | B37: 29 | C37: 31 | D37: 34 | E37: 36 | G37: 大小攻 | H37: 2 | I37: =H37*$D$37/2 -> 34 | K37: 大小攻 | M37: =L37*$D$37 -> 0
A38: 根骨 | B38: =$B$33 -> 7 | C38: =$C$33 -> 8 | D38: =$D$33 -> 9 | E38: =$E$33 -> 10 | G38: 根骨 | H38: 2 | I38: =H38*$D$38 -> 18 | K38: 根骨 | M38: =L38*$D$38 -> 0 | R38: =1/(1+EXP(1-(E7+G11)/G3)) -> 0.47800716
A39: 耐力 | B39: =$B$33 -> 7 | C39: =$C$33 -> 8 | D39: =$D$33 -> 9 | E39: =$E$33 -> 10 | G39: 耐力 | H39: 2 | I39: =H39*$D$39 -> 18 | K39: 耐力 | M39: =L39*$D$39 -> 0 | R39: =1/(1+EXP(1-E7/G3)) -> 0.44912038
A40: 防御 | B40: =$B$31 -> 26 | C40: =$C$31 -> 28 | D40: =$D$31 -> 31 | E40: =$E$31 -> 33 | H40: =SUM(H31:H37)+(H38+H39)/2 -> 21 | L40: =SUM(L31:L37)+(L38+L39)/2 -> 24
...
